Workbook
Name Slicer_AGE_RANGE: #N/A
Name Slicer_CNT_FAM_MEMBERS: #N/A
Name Slicer_CODE_GENDER: #N/A
Name Slicer_EMPLOYMENT_STATUS: #N/A
Name Slicer_NAME_EDUCATION_TYPE: #N/A
Name Slicer_NAME_FAMILY_STATUS: #N/A
Name Slicer_NAME_HOUSING_TYPE: #N/A
Name Slicer_NAME_INCOME_TYPE: #N/A

Sheet Data
A1: ID | B1: CODE_GENDER | C1: FLAG_OWN_CAR | D1: FLAG_OWN_REALTY | E1: CNT_CHILDREN | F1: AMT_INCOME_TOTAL | G1: NAME_INCOME_TYPE | H1: NAME_EDUCATION_TYPE | I1: NAME_FAMILY_STATUS | J1: NAME_HOUSING_TYPE | K1: DATE_OF_BIRTH | L1: DAYS_BIRTH | M1: AGE | N1: AGE_RANGE | O1: DAYS_EMPLOYED | P1: YEARS_EMPLOYED | Q1: EMPLOYMENT_STATUS | R1: FLAG_MOBIL | S1: FLAG_WORK_PHONE | T1: FLAG_PHONE | U1: FLAG_EMAIL | V1: OCCUPATION_TYPE | W1: CNT_FAM_MEMBERS
A2: 5008814 | B2: F | C2: N | D2: Y | E2: 0 | F2: 283500 | G2: Pensioner | H2: Higher education | I2: Separated | J2: House / apartment | K2: =TODAY()+($L2) -> 23297 | L2: -22464 | M2: =(TODAY()-K2)/365.25 -> 61.50308 | N2: =VLOOKUP(Data!M2,temp!$B$3:$C$9,2,1) -> 60-70 | O2: 365243 | P2: =IF(O2<=0,ABS(O2)/365.25,0) -> 0 | Q2: =IF($O2>0,"Unemployed","Employed") -> Unemployed | R2: 1 | S2: 0 | T2: 0 | U2: 0 | W2: 1
A3: 5008824 | B3: M | C3: Y | D3: Y | E3: 0 | F3: 135000 | G3: Commercial associate | H3: Secondary / secondary special | I3: Married | J3: House / apartment | K3: =TODAY()+($L3) -> 27983 | L3: -17778 | M3: =(TODAY()-K3)/365.25 -> 48.673511 | N3: =VLOOKUP(Data!M3,temp!$B$3:$C$9,2,1) -> 40-50 | O3: -1194 | P3: =IF(O3<=0,ABS(O3)/365.25,0) -> 3.2689938 | Q3: =IF($O3>0,"Unemployed","Employed") -> Employed | R3: 1 | S3: 0 | T3: 0 | U3: 0 | V3: Laborers | W3: 2
A4: 5008847 | B4: M | C4: Y | D4: Y | E4: 0 | F4: 112500 | G4: Commercial associate | H4: Secondary / secondary special | I4: Married | J4: House / apartment | K4: =TODAY()+($L4) -> 25259 | L4: -20502 | M4: =(TODAY()-K4)/365.25 -> 56.131417 | N4: =VLOOKUP(Data!M4,temp!$B$3:$C$9,2,1) -> 50-60 | O4: -4450 | P4: =IF(O4<=0,ABS(O4)/365.25,0) -> 12.183436 | Q4: =IF($O4>0,"Unemployed","Employed") -> Employed | R4: 1 | S4: 0 | T4: 1 | U4: 0 | V4: Drivers | W4: 2
A5: 5008854 | B5: F | C5: Y | D5: Y | E5: 2 | F5: 135000 | G5: Working | H5: Secondary / secondary special | I5: Married | J5: House / apartment | K5: =TODAY()+($L5) -> 30000 | L5: -15761 | M5: =(TODAY()-K5)/365.25 -> 43.151266 | N5: =VLOOKUP(Data!M5,temp!$B$3:$C$9,2,1) -> 40-50 | O5: -3173 | P5: =IF(O5<=0,ABS(O5)/365.25,0) -> 8.6872005 | Q5: =IF($O5>0,"Unemployed","Employed") -> Employed | R5: 1 | S5: 0 | T5: 0 | U5: 0 | V5: Laborers | W5: 4
A6: 5008856 | B6: F | C6: Y | D6: Y | E6: 2 | F6: 135000 | G6: Working | H6: Secondary / secondary special | I6: Married | J6: House / apartment | K6: =TODAY()+($L6) -> 30000 | L6: -15761 | M6: =(TODAY()-K6)/365.25 -> 43.151266 | N6: =VLOOKUP(Data!M6,temp!$B$3:$C$9,2,1) -> 40-50 | O6: -3173 | P6: =IF(O6<=0,ABS(O6)/365.25,0) -> 8.6872005 | Q6: =IF($O6>0,"Unemployed","Employed") -> Employed | R6: 1 | S6: 0 | T6: 0 | U6: 0 | V6: Laborers | W6: 4
A7: 5008863 | B7: F | C7: Y | D7: Y | E7: 2 | F7: 135000 | G7: Working | H7: Secondary / secondary special | I7: Married | J7: House / apartment | K7: =TODAY()+($L7) -> 30000 | L7: -15761 | M7: =(TODAY()-K7)/365.25 -> 43.151266 | N7: =VLOOKUP(Data!M7,temp!$B$3:$C$9,2,1) -> 40-50 | O7: -3173 | P7: =IF(O7<=0,ABS(O7)/365.25,0) -> 8.6872005 | Q7: =IF($O7>0,"Unemployed","Employed") -> Employed | R7: 1 | S7: 0 | T7: 0 | U7: 0 | V7: Laborers | W7: 4
A8: 5008865 | B8: F | C8: Y | D8: Y | E8: 2 | F8: 135000 | G8: Working | H8: Secondary / secondary special | I8: Married | J8: House / apartment | K8: =TODAY()+($L8) -> 30000 | L8: -15761 | M8: =(TODAY()-K8)/365.25 -> 43.151266 | N8: =VLOOKUP(Data!M8,temp!$B$3:$C$9,2,1) -> 40-50 | O8: -3173 | P8: =IF(O8<=0,ABS(O8)/365.25,0) -> 8.6872005 | Q8: =IF($O8>0,"Unemployed","Employed") -> Employed | R8: 1 | S8: 0 | T8: 0 | U8: 0 | V8: Laborers | W8: 4
A9: 5008875 | B9: F | C9: N | D9: Y | E9: 2 | F9: 126000 | G9: Commercial associate | H9: Higher education | I9: Married | J9: House / apartment | K9: =TODAY()+($L9) -> 33350 | L9: -12411 | M9: =(TODAY()-K9)/365.25 -> 33.979466 | N9: =VLOOKUP(Data!M9,temp!$B$3:$C$9,2,1) -> 30-40 | O9: -1773 | P9: =IF(O9<=0,ABS(O9)/365.25,0) -> 4.8542094 | Q9: =IF($O9>0,"Unemployed","Employed") -> Employed | R9: 1 | S9: 0 | T9: 0 | U9: 1 | V9: Managers | W9: 4
A10: 5008877 | B10: F | C10: N | D10: Y | E10: 2 | F10: 126000 | G10: Commercial associate | H10: Higher education | I10: Married | J10: House / apartment | K10: =TODAY()+($L10) -> 33350 | L10: -12411 | M10: =(TODAY()-K10)/365.25 -> 33.979466 | N10: =VLOOKUP(Data!M10,temp!$B$3:$C$9,2,1) -> 30-40 | O10: -1773 | P10: =IF(O10<=0,ABS(O10)/365.25,0) -> 4.8542094 | Q10: =IF($O10>0,"Unemployed","Employed") -> Employed | R10: 1 | S10: 0 | T10: 0 | U10: 1 | V10: Managers | W10: 4
A11: 5008892 | B11: F | C11: N | D11: Y | E11: 0 | F11: 297000 | G11: Commercial associate | H11: Secondary / secondary special | I11: Single / not married | J11: Rented apartment | K11: =TODAY()+($L11) -> 30242 | L11: -15519 | M11: =(TODAY()-K11)/365.25 -> 42.488706 | N11: =VLOOKUP(Data!M11,temp!$B$3:$C$9,2,1) -> 40-50 | O11: -3234 | P11: =IF(O11<=0,ABS(O11)/365.25,0) -> 8.8542094 | Q11: =IF($O11>0,"Unemployed","Employed") -> Employed | R11: 1 | S11: 0 | T11: 0 | U11: 0 | V11: Laborers | W11: 1
A12: 5008893 | B12: F | C12: N | D12: Y | E12: 0 | F12: 297000 | G12: Commercial associate | H12: Secondary / secondary special | I12: Single / not married | J12: Rented apartment | K12: =TODAY()+($L12) -> 30242 | L12: -15519 | M12: =(TODAY()-K12)/365.25 -> 42.488706 | N12: =VLOOKUP(Data!M12,temp!$B$3:$C$9,2,1) -> 40-50 | O12: -3234 | P12: =IF(O12<=0,ABS(O12)/365.25,0) -> 8.8542094 | Q12: =IF($O12>0,"Unemployed","Employed") -> Employed | R12: 1 | S12: 0 | T12: 0 | U12: 0 | V12: Laborers | W12: 1
A13: 5008896 | B13: F | C13: N | D13: Y | E13: 0 | F13: 297000 | G13: Commercial associate | H13: Secondary / secondary special | I13: Single / not married | J13: Rented apartment | K13: =TODAY()+($L13) -> 30242 | L13: -15519 | M13: =(TODAY()-K13)/365.25 -> 42.488706 | N13: =VLOOKUP(Data!M13,temp!$B$3:$C$9,2,1) -> 40-50 | O13: -3234 | P13: =IF(O13<=0,ABS(O13)/365.25,0) -> 8.8542094 | Q13: =IF($O13>0,"Unemployed","Employed") -> Employed | R13: 1 | S13: 0 | T13: 0 | U13: 0 | V13: Laborers | W13: 1
A14: 5008900 | B14: F | C14: N | D14: Y | E14: 0 | F14: 297000 | G14: Commercial associate | H14: Secondary / secondary special | I14: Single / not married | J14: Rented apartment | K14: =TODAY()+($L14) -> 30242 | L14: -15519 | M14: =(TODAY()-K14)/365.25 -> 42.488706 | N14: =VLOOKUP(Data!M14,temp!$B$3:$C$9,2,1) -> 40-50 | O14: -3234 | P14: =IF(O14<=0,ABS(O14)/365.25,0) -> 8.8542094 | Q14: =IF($O14>0,"Unemployed","Employed") -> Employed | R14: 1 | S14: 0 | T14: 0 | U14: 0 | V14: Laborers | W14: 1
... A20: 5008937 | B20: F | C20: N | D20: Y | E20: 0 | F20: 297000 | G20: Commercial associate | H20: Secondary / secondary special | I20: Single / not married | J20: Rented apartment | K20: =TODAY()+($L20) -> 30242 | L20: -15519 | M20: =(TODAY()-K20)/365.25 -> 42.488706 | N20: =VLOOKUP(Data!M20,temp!$B$3:$C$9,2,1) -> 40-50 | O20: -3234 | P20: =IF(O20<=0,ABS(O20)/365.25,0) -> 8.8542094 | Q20: =IF($O20>0,"Unemployed","Employed") -> Employed | R20: 1 | S20: 0 | T20: 0 | U20: 0 | V20: Laborers | W20: 1
A21: 5008973 | B21: M | C21: N | D21: Y | E21: 0 | F21: 157500 | G21: Working | H21: Secondary / secondary special | I21: Married | J21: House / apartment | K21: =TODAY()+($L21) -> 29734 | L21: -16027 | M21: =(TODAY()-K21)/365.25 -> 43.879535 | N21: =VLOOKUP(Data!M21,temp!$B$3:$C$9,2,1) -> 40-50 | O21: -889 | P21: =IF(O21<=0,ABS(O21)/365.25,0) -> 2.4339493 | Q21: =IF($O21>0,"Unemployed","Employed") -> Employed | R21: 1 | S21: 0 | T21: 1 | U21: 0 | W21: 2
A22: 5008978 | B22: F | C22: N | D22: Y | E22: 0 | F22: 112500 | G22: Pensioner | H22: Secondary / secondary special | I22: Married | J22: House / apartment | K22: =TODAY()+($L22) -> 23442 | L22: -22319 | M22: =(TODAY()-K22)/365.25 -> 61.106092 | N22: =VLOOKUP(Data!M22,temp!$B$3:$C$9,2,1) -> 60-70 | O22: 365243 | P22: =IF(O22<=0,ABS(O22)/365.25,0) -> 0 | Q22: =IF($O22>0,"Unemployed","Employed") -> Unemployed | R22: 1 | S22: 0 | T22: 0 | U22: 0 | W22: 2
A23: 5008986 | B23: M | C23: Y | D23: Y | E23: 0 | F23: 112500 | G23: State servant | H23: Secondary / secondary special | I23: Married | J23: House / apartment | K23: =TODAY()+($L23) -> 24887 | L23: -20874 | M23: =(TODAY()-K23)/365.25 -> 57.149897 | N23: =VLOOKUP(Data!M23,temp!$B$3:$C$9,2,1) -> 50-60 | O23: -2381 | P23: =IF(O23<=0,ABS(O23)/365.25,0) -> 6.5188227 | Q23: =IF($O23>0,"Unemployed","Employed") -> Employed | R23: 1 | S23: 0 | T23: 1 | U23: 0 | V23: Drivers | W23: 2
A24: 5009005 | B24: M | C24: N | D24: Y | E24: 0 | F24: 166500 | G24: Working | H24: Secondary / secondary special | I24: Married | J24: House / apartment | K24: =TODAY()+($L24) -> 26835 | L24: -18926 | M24: =(TODAY()-K24)/365.25 -> 51.816564 | N24: =VLOOKUP(Data!M24,temp!$B$3:$C$9,2,1) -> 50-60 | O24: -6276 | P24: =IF(O24<=0,ABS(O24)/365.25,0) -> 17.182752 | Q24: =IF($O24>0,"Unemployed","Employed") -> Employed | R24: 1 | S24: 1 | T24: 1 | U24: 0 | V24: Laborers | W24: 2
A25: 5009006 | B25: M | C25: N | D25: Y | E25: 0 | F25: 166500 | G25: Working | H25: Secondary / secondary special | I25: Married | J25: House / apartment | K25: =TODAY()+($L25) -> 26835 | L25: -18926 | M25: =(TODAY()-K25)/365.25 -> 51.816564 | N25: =VLOOKUP(Data!M25,temp!$B$3:$C$9,2,1) -> 50-60 | O25: -6276 | P25: =IF(O25<=0,ABS(O25)/365.25,0) -> 17.182752 | Q25: =IF($O25>0,"Unemployed","Employed") -> Employed | R25: 1 | S25: 1 | T25: 1 | U25: 0 | V25: Laborers | W25: 2
A26: 5009009 | B26: M | C26: N | D26: Y | E26: 0 | F26: 166500 | G26: Working | H26: Secondary / secondary special | I26: Married | J26: House / apartment | K26: =TODAY()+($L26) -> 26835 | L26: -18926 | M26: =(TODAY()-K26)/365.25 -> 51.816564 | N26: =VLOOKUP(Data!M26,temp!$B$3:$C$9,2,1) -> 50-60 | O26: -6276 | P26: =IF(O26<=0,ABS(O26)/365.25,0) -> 17.182752 | Q26: =IF($O26>0,"Unemployed","Employed") -> Employed | R26: 1 | S26: 1 | T26: 1 | U26: 0 | V26: Laborers | W26: 2
A27: 5009014 | B27: M | C27: N | D27: Y | E27: 0 | F27: 166500 | G27: Working | H27: Secondary / secondary special | I27: Married | J27: House / apartment | K27: =TODAY()+($L27) -> 26835 | L27: -18926 | M27: =(TODAY()-K27)/365.25 -> 51.816564 | N27: =VLOOKUP(Data!M27,temp!$B$3:$C$9,2,1) -> 50-60 | O27: -6276 | P27: =IF(O27<=0,ABS(O27)/365.25,0) -> 17.182752 | Q27: =IF($O27>0,"Unemployed","Employed") -> Employed | R27: 1 | S27: 1 | T27: 1 | U27: 0 | V27: Laborers | W27: 2
A28: 5009025 | B28: F | C28: N | D28: Y | E28: 2 | F28: 216000 | G28: State servant | H28: Higher education | I28: Married | J28: House / apartment | K28: =TODAY()+($L28) -> 30317 | L28: -15444 | M28: =(TODAY()-K28)/365.25 -> 42.283368 | N28: =VLOOKUP(Data!M28,temp!$B$3:$C$9,2,1) -> 40-50 | O28: -3112 | P28: =IF(O28<=0,ABS(O28)/365.25,0) -> 8.5201916 | Q28: =IF($O28>0,"Unemployed","Employed") -> Employed | R28: 1 | S28: 0 | T28: 0 | U28: 1 | W28: 4
A29: 5009029 | B29: F | C29: Y | D29: Y | E29: 0 | F29: 225000 | G29: Commercial associate | H29: Secondary / secondary special | I29: Married | J29: House / apartment | K29: =TODAY()+($L29) -> 31311 | L29: -14450 | M29: =(TODAY()-K29)/365.25 -> 39.561944 | N29: =VLOOKUP(Data!M29,temp!$B$3:$C$9,2,1) -> 30-40 | O29: -2777 | P29: =IF(O29<=0,ABS(O29)/365.25,0) -> 7.6030116 | Q29: =IF($O29>0,"Unemployed","Employed") -> Employed | R29: 1 | S29: 0 | T29: 0 | U29: 0 | V29: Laborers | W29: 2
A30: 5009033 | B30: F | C30: N | D30: N | E30: 0 | F30: 255150 | G30: Pensioner | H30: Incomplete higher | I30: Civil marriage | J30: Rented apartment | K30: =TODAY()+($L30) -> 27079 | L30: -18682 | M30: =(TODAY()-K30)/365.25 -> 51.148528 | N30: =VLOOKUP(Data!M30,temp!$B$3:$C$9,2,1) -> 50-60 | O30: 365243 | P30: =IF(O30<=0,ABS(O30)/365.25,0) -> 0 | Q30: =IF($O30>0,"Unemployed","Employed") -> Unemployed | R30: 1 | S30: 0 | T30: 0 | U30: 0 | W30: 2
A31: 5009036 | B31: F | C31: N | D31: N | E31: 0 | F31: 255150 | G31: Pensioner | H31: Incomplete higher | I31: Civil marriage | J31: Rented apartment | K31: =TODAY()+($L31) -> 27079 | L31: -18682 | M31: =(TODAY()-K31)/365.25 -> 51.148528 | N31: =VLOOKUP(Data!M31,temp!$B$3:$C$9,2,1) -> 50-60 | O31: 365243 | P31: =IF(O31<=0,ABS(O31)/365.25,0) -> 0 | Q31: =IF($O31>0,"Unemployed","Employed") -> Unemployed | R31: 1 | S31: 0 | T31: 0 | U31: 0 | W31: 2
A32: 5009038 | B32: F | C32: N | D32: N | E32: 0 | F32: 255150 | G32: Pensioner | H32: Incomplete higher | I32: Civil marriage | J32: Rented apartment | K32: =TODAY()+($L32) -> 27079 | L32: -18682 | M32: =(TODAY()-K32)/365.25 -> 51.148528 | N32: =VLOOKUP(Data!M32,temp!$B$3:$C$9,2,1) -> 50-60 | O32: 365243 | P32: =IF(O32<=0,ABS(O32)/365.25,0) -> 0 | Q32: =IF($O32>0,"Unemployed","Employed") -> Unemployed | R32: 1 | S32: 0 | T32: 0 | U32: 0 | W32: 2
A33: 5009046 | B33: F | C33: N | D33: Y | E33: 0 | F33: 148500 | G33: Working | H33: Higher education | I33: Married | J33: House / apartment | K33: =TODAY()+($L33) -> 28120 | L33: -17641 | M33: =(TODAY()-K33)/365.25 -> 48.298426 | N33: =VLOOKUP(Data!M33,temp!$B$3:$C$9,2,1) -> 40-50 | O33: -889 | P33: =IF(O33<=0,ABS(O33)/365.25,0) -> 2.4339493 | Q33: =IF($O33>0,"Unemployed","Employed") -> Employed | R33: 1 | S33: 0 | T33: 0 | U33: 0 | V33: Core staff | W33: 2
A34: 5009052 | B34: F | C34: N | D34: Y | E34: 2 | F34: 202500 | G34: Working | H34: Higher education | I34: Married | J34: House / apartment | K34: =TODAY()+($L34) -> 34764 | L34: -10997 | M34: =(TODAY()-K34)/365.25 -> 30.108145 | N34: =VLOOKUP(Data!M34,temp!$B$3:$C$9,2,1) -> 30-40 | O34: -2289 | P34: =IF(O34<=0,ABS(O34)/365.25,0) -> 6.2669405 | Q34: =IF($O34>0,"Unemployed","Employed") -> Employed | R34: 1 | S34: 0 | T34: 0 | U34: 1 | V34: Core staff | W34: 4
A35: 5009056 | B35: M | C35: N | D35: Y | E35: 0 | F35: 202500 | G35: Working | H35: Secondary / secondary special | I35: Single / not married | J35: House / apartment | K35: =TODAY()+($L35) -> 36900 | L35: -8861 | M35: =(TODAY()-K35)/365.25 -> 24.260096 | N35: =VLOOKUP(Data!M35,temp!$B$3:$C$9,2,1) -> 20-30 | O35: -889 | P35: =IF(O35<=0,ABS(O35)/365.25,0) -> 2.4339493 | Q35: =IF($O35>0,"Unemployed","Employed") -> Employed | R35: 1 | S35: 1 | T35: 0 | U35: 0 | V35: Drivers | W35: 1
A36: 5009065 | B36: M | C36: Y | D36: Y | E36: 0 | F36: 315000 | G36: Working | H36: Secondary / secondary special | I36: Civil marriage | J36: House / apartment | K36: =TODAY()+($L36) -> 35311 | L36: -10450 | M36: =(TODAY()-K36)/365.25 -> 28.610541 | N36: =VLOOKUP(Data!M36,temp!$B$3:$C$9,2,1) -> 20-30 | O36: -2077 | P36: =IF(O36<=0,ABS(O36)/365.25,0) -> 5.6865161 | Q36: =IF($O36>0,"Unemployed","Employed") -> Employed | R36: 1 | S36: 0 | T36: 0 | U36: 0 | V36: Sales staff | W36: 2
A37: 5009066 | B37: M | C37: Y | D37: Y | E37: 0 | F37: 315000 | G37: Working | H37: Secondary / secondary special | I37: Civil marriage | J37: House / apartment | K37: =TODAY()+($L37) -> 35311 | L37: -10450 | M37: =(TODAY()-K37)/365.25 -> 28.610541 | N37: =VLOOKUP(Data!M37,temp!$B$3:$C$9,2,1) -> 20-30 | O37: -2077 | P37: =IF(O37<=0,ABS(O37)/365.25,0) -> 5.6865161 | Q37: =IF($O37>0,"Unemployed","Employed") -> Employed | R37: 1 | S37: 0 | T37: 0 | U37: 0 | V37: Sales staff | W37: 2
A38: 5009070 | B38: M | C38: Y | D38: Y | E38: 0 | F38: 315000 | G38: Working | H38: Secondary / secondary special | I38: Civil marriage | J38: House / apartment | K38: =TODAY()+($L38) -> 35311 | L38: -10450 | M38: =(TODAY()-K38)/365.25 -> 28.610541 | N38: =VLOOKUP(Data!M38,temp!$B$3:$C$9,2,1) -> 20-30 | O38: -2077 | P38: =IF(O38<=0,ABS(O38)/365.25,0) -> 5.6865161 | Q38: =IF($O38>0,"Unemployed","Employed") -> Employed | R38: 1 | S38: 0 | T38: 0 | U38: 0 | V38: Sales staff | W38: 2
A39: 5009081 | B39: F | C39: N | D39: Y | E39: 0 | F39: 112500 | G39: Working | H39: Higher education | I39: Civil marriage | J39: House / apartment | K39: =TODAY()+($L39) -> 35697 | L39: -10064 | M39: =(TODAY()-K39)/365.25 -> 27.55373 | N39: =VLOOKUP(Data!M39,temp!$B$3:$C$9,2,1) -> 20-30 | O39: -3173 | P39: =IF(O39<=0,ABS(O39)/365.25,0) -> 8.6872005 | Q39: =IF($O39>0,"Unemployed","Employed") -> Employed | R39: 1 | S39: 0 | T39: 0 | U39: 1 | V39: Laborers | W39: 2
A40: 5009094 | B40: M | C40: Y | D40: Y | E40: 1 | F40: 765000 | G40: Working | H40: Higher education | I40: Married | J40: House / apartment | K40: =TODAY()+($L40) -> 33564 | L40: -12197 | M40: =(TODAY()-K40)/365.25 -> 33.393566 | N40: =VLOOKUP(Data!M40,temp!$B$3:$C$9,2,1) -> 30-40 | O40: -1194 | P40: =IF(O40<=0,ABS(O40)/365.25,0) -> 3.2689938 | Q40: =IF($O40>0,"Unemployed","Employed") -> Employed | R40: 1 | S40: 1 | T40: 0 | U40: 0 | V40: Managers | W40: 3
A41: 5009108 | B41: M | C41: N | D41: Y | E41: 0 | F41: 360000 | G41: Commercial associate | H41: Secondary / secondary special | I41: Married | J41: House / apartment | K41: =TODAY()+($L41) -> 30440 | L41: -15321 | M41: =(TODAY()-K41)/365.25 -> 41.946612 | N41: =VLOOKUP(Data!M41,temp!$B$3:$C$9,2,1) -> 40-50 | O41: -2747 | P41: =IF(O41<=0,ABS(O41)/365.25,0) -> 7.5208761 | Q41: =IF($O41>0,"Unemployed","Employed") -> Employed | R41: 1 | S41: 0 | T41: 0 | U41: 0 | V41: Security staff | W41: 2
A42: 5009125 | B42: F | C42: N | D42: N | E42: 0 | F42: 157500 | G42: Commercial associate | H42: Higher education | I42: Separated | J42: With parents | K42: =TODAY()+($L42) -> 30024 | L42: -15737 | M42: =(TODAY()-K42)/365.25 -> 43.085558 | N42: =VLOOKUP(Data!M42,temp!$B$3:$C$9,2,1) -> 40-50 | O42: -432 | P42: =IF(O42<=0,ABS(O42)/365.25,0) -> 1.1827515 | Q42: =IF($O42>0,"Unemployed","Employed") -> Employed | R42: 1 | S42: 0 | T42: 0 | U42: 0 | W42: 1
A43: 5009133 | B43: M | C43: N | D43: Y | E43: 0 | F43: 382500 | G43: Pensioner | H43: Secondary / secondary special | I43: Widow | J43: House / apartment | K43: =TODAY()+($L43) -> 24088 | L43: -21673 | M43: =(TODAY()-K43)/365.25 -> 59.33744 | N43: =VLOOKUP(Data!M43,temp!$B$3:$C$9,2,1) -> 50-60 | O43: 365243 | P43: =IF(O43<=0,ABS(O43)/365.25,0) -> 0 | Q43: =IF($O43>0,"Unemployed","Employed") -> Unemployed | R43: 1 | S43: 0 | T43: 0 | U43: 0 | W43: 1
A44: 5009138 | B44: M | C44: N | D44: Y | E44: 0 | F44: 382500 | G44: Pensioner | H44: Secondary / secondary special | I44: Widow | J44: House / apartment | K44: =TODAY()+($L44) -> 24088 | L44: -21673 | M44: =(TODAY()-K44)/365.25 -> 59.33744 | N44: =VLOOKUP(Data!M44,temp!$B$3:$C$9,2,1) -> 50-60 | O44: 365243 | P44: =IF(O44<=0,ABS(O44)/365.25,0) -> 0 | Q44: =IF($O44>0,"Unemployed","Employed") -> Unemployed | R44: 1 | S44: 0 | T44: 0 | U44: 0 | W44: 1
A45: 5009141 | B45: F | C45: N | D45: N | E45: 0 | F45: 135000 | G45: Working | H45: Secondary / secondary special | I45: Civil marriage | J45: House / apartment | K45: =TODAY()+($L45) -> 36104 | L45: -9657 | M45: =(TODAY()-K45)/365.25 -> 26.439425 | N45: =VLOOKUP(Data!M45,temp!$B$3:$C$9,2,1) -> 20-30 | O45: -1560 | P45: =IF(O45<=0,ABS(O45)/365.25,0) -> 4.2710472 | Q45: =IF($O45>0,"Unemployed","Employed") -> Employed | R45: 1 | S45: 1 | T45: 1 | U45: 0 | V45: Managers | W45: 2
...

Sheet temp
B1: AGE | C1: AGE RANGE
B3: 10 | C3: 10-20
B4: 20 | C4: 20-30
B5: 30 | C5: 30-40
B6: 40 | C6: 40-50
B7: 50 | C7: 50-60
B8: 60 | C8: 60-70
B9: 70 | C9: 70-80

Sheet Pivot table 1
A3: Count of CODE_GENDER | B3: Gender
A4: Age Group | B4: F | C4: M | D4: Grand Total
A5: 20-30 | B5: 314 | C5: 326 | D5: 640
A6: 30-40 | B6: 863 | C6: 465 | D6: 1328
A7: 40-50 | B7: 789 | C7: 392 | D7: 1181
A8: 50-60 | B8: 757 | C8: 241 | D8: 998
A9: 60-70 | B9: 351 | C9: 84 | D9: 435
A10: Grand Total | B10: 3074 | C10: 1508 | D10: 4582

Sheet Pivot table 2
A4: Count of CODE_GENDER | B4: Gender
A5: Education type | B5: F | C5: M | D5: Grand Total
A6: Academic degree | B6: 4 | D6: 4
A7: Higher education | B7: 852 | C7: 387 | D7: 1239
A8: Incomplete higher | B8: 106 | C8: 75 | D8: 181
A9: Lower secondary | B9: 40 | C9: 14 | D9: 54
A10: Secondary / secondary special | B10: 2072 | C10: 1032 | D10: 3104
A11: Grand Total | B11: 3074 | C11: 1508 | D11: 4582

Sheet Pivot table_3
A3: Employment Status | B3: Count of ID
A4: Employed | B4: 3854
A5: Unemployed | B5: 728
A6: Grand Total | B6: 4582

Sheet Pivot table 4
A3: Average of AMT_INCOME_TOTAL | B3: Count of fam members
A4: Name Income Type | B4: 1 | C4: 2 | D4: 3 | E4: 4 | F4: 5 | G4: 6 | H4: 7 | I4: Grand Total
A5: Commercial associate | B5: 222994.34 | C5: 215747.79 | D5: 210988.12 | E5: 191927.42 | F5: 127350 | G5: 150000 | I5: 212983.32
A6: Pensioner | B6: 148699.76 | C6: 144677 | D6: 167135.29 | E6: 111500 | F6: 292500 | I6: 146530.68
A7: State servant | B7: 191700 | C7: 200086.14 | D7: 217269.23 | E7: 232402.5 | F7: 123500 | G7: 202500 | I7: 205334.41
A8: Student | D8: 112500 | I8: 112500
A9: Working | B9: 179637.87 | C9: 187060.04 | D9: 183282.14 | E9: 177390 | F9: 158958.62 | G9: 162000 | H9: 135000 | I9: 183530.63
A10: Grand Total | B10: 182670.33 | C10: 186140.29 | D10: 194163.24 | E10: 187488.81 | F10: 154358.82 | G10: 171500 | H10: 135000 | I10: 186629.92

Sheet Pivot table 5
A3: Housing Type | B3: Count of CNT_FAM_MEMBERS
A4: Co-op apartment | B4: 23
A5: House / apartment | B5: 4081
A6: Municipal apartment | B6: 144
A7: Office apartment | B7: 36
A8: Rented apartment | B8: 78
A9: With parents | B9: 220
A10: Grand Total | B10: 4582

Sheet Pivot table 6
A3: Count of EMPLOYMENT_STATUS | B3: Emp Status
A4: Family Status | B4: Employed | C4: Unemployed | D4: Grand Total
A5: Civil marriage | B5: 328 | C5: 39 | D5: 367
A6: Married | B6: 2681 | C6: 484 | D6: 3165
A7: Separated | B7: 189 | C7: 31 | D7: 220
A8: Single / not married | B8: 556 | C8: 75 | D8: 631
A9: Widow | B9: 100 | C9: 99 | D9: 199
A10: Grand Total | B10: 3854 | C10: 728 | D10: 4582

Sheet Add inf
A2: STEPS | D2: KPIs (Key Performance Indicators)
B3: 1) | C3: Explaining the data set and analysis. | D3: Count of Gender by Age Group.
B4: 2) | C4: Identifying KPIs. | D4: Count of Gender by Education Status.
B5: 3) | C5: Creating dashboard. | D5: Count of Employed and Unemployed.
B6: 4) | C6: Sharing actionable business insights. | D6: Average Total Income Acc to Income type and and Count of Family members.
D7: Count of Family members Acc to Housing type.
D8: Employment and Unemployment according to Name Family Status.

Sheet DASH BOARD
A1: XYZ COMPANY
